[2024-07-30T19:34:46.389+0000] {local_task_job_runner.py:120} INFO - ::group::Pre task execution logs
[2024-07-30T19:34:46.405+0000] {taskinstance.py:2076} INFO - Dependencies all met for dep_context=non-requeueable deps ti=<TaskInstance: zillow-analytics-dag.tsk_extract_zillow_data_var manual__2024-07-30T19:34:25.193812+00:00 [queued]>
[2024-07-30T19:34:46.411+0000] {taskinstance.py:2076} INFO - Dependencies all met for dep_context=requeueable deps ti=<TaskInstance: zillow-analytics-dag.tsk_extract_zillow_data_var manual__2024-07-30T19:34:25.193812+00:00 [queued]>
[2024-07-30T19:34:46.411+0000] {taskinstance.py:2306} INFO - Starting attempt 2 of 3
[2024-07-30T19:34:46.426+0000] {taskinstance.py:2330} INFO - Executing <Task(PythonOperator): tsk_extract_zillow_data_var> on 2024-07-30 19:34:25.193812+00:00
[2024-07-30T19:34:46.430+0000] {standard_task_runner.py:64} INFO - Started process 1858 to run task
[2024-07-30T19:34:46.433+0000] {standard_task_runner.py:90} INFO - Running: ['airflow', 'tasks', 'run', 'zillow-analytics-dag', 'tsk_extract_zillow_data_var', 'manual__2024-07-30T19:34:25.193812+00:00', '--job-id', '16', '--raw', '--subdir', 'DAGS_FOLDER/zillowanalytics.py', '--cfg-path', '/tmp/tmpmpbrl1i4']
[2024-07-30T19:34:46.434+0000] {standard_task_runner.py:91} INFO - Job 16: Subtask tsk_extract_zillow_data_var
[2024-07-30T19:34:46.467+0000] {task_command.py:426} INFO - Running <TaskInstance: zillow-analytics-dag.tsk_extract_zillow_data_var manual__2024-07-30T19:34:25.193812+00:00 [running]> on host ip-172-31-16-43.eu-central-1.compute.internal
[2024-07-30T19:34:46.536+0000] {taskinstance.py:2648} INFO - Exporting env vars: AIRFLOW_CTX_DAG_EMAIL='yashvij1996@gmail.com' AIRFLOW_CTX_DAG_OWNER='Yash-First-Airflow-DAG' AIRFLOW_CTX_DAG_ID='zillow-analytics-dag' AIRFLOW_CTX_TASK_ID='tsk_extract_zillow_data_var' AIRFLOW_CTX_EXECUTION_DATE='2024-07-30T19:34:25.193812+00:00' AIRFLOW_CTX_TRY_NUMBER='2' AIRFLOW_CTX_DAG_RUN_ID='manual__2024-07-30T19:34:25.193812+00:00'
[2024-07-30T19:34:46.537+0000] {taskinstance.py:430} INFO - ::endgroup::
[2024-07-30T19:34:47.354+0000] {taskinstance.py:441} INFO - ::group::Post task execution logs
[2024-07-30T19:34:47.355+0000] {taskinstance.py:2905} ERROR - Task failed with exception
Traceback (most recent call last):
  File "/home/ubuntu/zillowdata_de_youtube_venv/lib/python3.12/site-packages/airflow/models/taskinstance.py", line 465, in _execute_task
    result = _execute_callable(context=context, **execute_callable_kwargs)
             ^^^^^^^^^^^^^^^^^^^^^^^^^^^^^^^^^^^^^^^^^^^^^^^^^^^^^^^^^^^^^
  File "/home/ubuntu/zillowdata_de_youtube_venv/lib/python3.12/site-packages/airflow/models/taskinstance.py", line 432, in _execute_callable
    return execute_callable(context=context, **execute_callable_kwargs)
           ^^^^^^^^^^^^^^^^^^^^^^^^^^^^^^^^^^^^^^^^^^^^^^^^^^^^^^^^^^^^
  File "/home/ubuntu/zillowdata_de_youtube_venv/lib/python3.12/site-packages/airflow/models/baseoperator.py", line 401, in wrapper
    return func(self, *args, **kwargs)
           ^^^^^^^^^^^^^^^^^^^^^^^^^^^
  File "/home/ubuntu/zillowdata_de_youtube_venv/lib/python3.12/site-packages/airflow/operators/python.py", line 235, in execute
    return_value = self.execute_callable()
                   ^^^^^^^^^^^^^^^^^^^^^^^
  File "/home/ubuntu/zillowdata_de_youtube_venv/lib/python3.12/site-packages/airflow/operators/python.py", line 252, in execute_callable
    return self.python_callable(*self.op_args, **self.op_kwargs)
           ^^^^^^^^^^^^^^^^^^^^^^^^^^^^^^^^^^^^^^^^^^^^^^^^^^^^^
  File "/home/ubuntu/airflow/dags/zillowanalytics.py", line 33, in extract_zillow_data
    with open(output_file_path, "w") as output_file :
         ^^^^^^^^^^^^^^^^^^^^^^^^^^^
FileNotFoundError: [Errno 2] No such file or directory: '/home/ubuntu/json_output/response_data_30072024193446.json'
[2024-07-30T19:34:47.360+0000] {taskinstance.py:1206} INFO - Marking task as UP_FOR_RETRY. dag_id=zillow-analytics-dag, task_id=tsk_extract_zillow_data_var, run_id=manual__2024-07-30T19:34:25.193812+00:00, execution_date=20240730T193425, start_date=20240730T193446, end_date=20240730T193447
[2024-07-30T19:34:47.372+0000] {standard_task_runner.py:110} ERROR - Failed to execute job 16 for task tsk_extract_zillow_data_var ([Errno 2] No such file or directory: '/home/ubuntu/json_output/response_data_30072024193446.json'; 1858)
[2024-07-30T19:34:47.407+0000] {local_task_job_runner.py:243} INFO - Task exited with return code 1
[2024-07-30T19:34:47.418+0000] {taskinstance.py:3503} INFO - 0 downstream tasks scheduled from follow-on schedule check
[2024-07-30T19:34:47.418+0000] {local_task_job_runner.py:222} INFO - ::endgroup::
